<?xml version="1.0" encoding="utf-8"?>
<!-- This URDF was automatically created by SolidWorks to URDF Exporter! Originally created by Stephen Brawner (brawner@gmail.com) 
     Commit Version: 1.6.0-1-g15f4949  Build Version: 1.6.7594.29634
     For more information, please see http://wiki.ros.org/sw_urdf_exporter -->
<robot
  name="vision1">
  <link name="dummylink">
  </link>
  <joint name="dummyjoint" type="fixed">
    <parent link="dummylink"/>
    <child link="chassis"/>
  </joint>
  <link
    name="chassis">
    <inertial>
      <origin
        xyz="-6.67048457508904E-17 -9.65107136094099E-17 0.0301859526129163"
        rpy="0 0 0" />
      <mass
        value="75.3982945732463" />
      <inertia
        ixx="37.6875461543528"
        ixy="9.93243680911644E-16"
        ixz="-2.51115452539207E-15"
        iyy="36.4599738843757"
        iyz="1.69476198366275E-14"
        izz="73.6477332288632" />
    </inertial>
    <visual>
      <origin
        xyz="0 0 0"
        rpy="0 0 0" />
      <geometry>
        <mesh
          filename="package://vision1/meshes/chassis.STL" />
      </geometry>
      <material
        name="">
        <color
          rgba="1 0.886274509803922 0.309803921568627 1" />
      </material>
    </visual>
    <collision>
      <origin
        xyz="0 0 0"
        rpy="0 0 0" />
      <geometry>
        <mesh
          filename="package://vision1/meshes/chassis.STL" />
      </geometry>
    </collision>
  </link>
  <link
    name="left_main">
    <inertial>
      <origin
        xyz="-0.187587214227298 -0.193829326981754 0.103350542447008"
        rpy="0 0 0" />
      <mass
        value="11.5796588524314" />
      <inertia
        ixx="0.104962702548715"
        ixy="-0.23703186835524"
        ixz="0.0084157586236052"
        iyy="2.53477008510846"
        iyz="-0.000365251532953697"
        izz="2.62636682146623" />
    </inertial>
    <visual>
      <origin
        xyz="0 0 0"
        rpy="0 0 0" />
      <geometry>
        <mesh
          filename="package://vision1/meshes/left_main.STL" />
      </geometry>
      <material
        name="">
        <color
          rgba="0.792156862745098 0.819607843137255 0.933333333333333 1" />
      </material>
    </visual>
    <collision>
      <origin
        xyz="0 0 0"
        rpy="0 0 0" />
      <geometry>
        <mesh
          filename="package://vision1/meshes/left_main.STL" />
      </geometry>
    </collision>
  </link>
  <joint
    name="left_main_joint"
    type="fixed">
    <origin
      xyz="0 0.996 0.1527"
      rpy="1.5708 0.12191 -3.1416" />
    <parent
      link="chassis" />
    <child
      link="left_main" />
    <axis
      xyz="0 0 1" />
    
  </joint>
  <link
    name="left_front_whlconnect">
    <inertial>
      <origin
        xyz="0.0919368788373029 -0.303078537800269 2.97809443772223E-09"
        rpy="0 0 0" />
      <mass
        value="10.0922799476841" />
      <inertia
        ixx="0.180451958547416"
        ixy="0.021786782051187"
        ixz="1.11127781109166E-09"
        iyy="0.0734598583330053"
        iyz="5.98564580431109E-09"
        izz="0.239851150726298" />
    </inertial>
    <visual>
      <origin
        xyz="0 0 0"
        rpy="0 0 0" />
      <geometry>
        <mesh
          filename="package://vision1/meshes/left_front_whlconnect.STL" />
      </geometry>
      <material
        name="">
        <color
          rgba="0.792156862745098 0.819607843137255 0.933333333333333 1" />
      </material>
    </visual>
    <collision>
      <origin
        xyz="0 0 0"
        rpy="0 0 0" />
      <geometry>
        <mesh
          filename="package://vision1/meshes/left_front_whlconnect.STL" />
      </geometry>
    </collision>
  </link>
  <joint
    name="left_front_whlconnect_joint"
    type="revolute">
    <origin
      xyz="-0.7809 -0.46022 0.104"
      rpy="3.1416 1.5062 3.1416" />
    <parent
      link="left_main" />
    <child
      link="left_front_whlconnect" />
    <axis
      xyz="0 1 0" />
    <limit
      lower="-1.0"
      upper="1.0"
      effort="100"
      velocity="10" />
  </joint>
  <link
    name="left_front_wheel">
    <inertial>
      <origin
        xyz="-0.0726272967322998 2.22044604925031E-16 2.72004641033163E-14"
        rpy="0 0 0" />
      <mass
        value="24.6135816790046" />
      <inertia
        ixx="1.49233859783078"
        ixy="-5.42488484689407E-11"
        ixz="-5.59634307211593E-11"
        iyy="0.941453197285766"
        iyz="5.63490904327904E-14"
        izz="0.941453197282353" />
    </inertial>
    <visual>
      <origin
        xyz="0 0 0"
        rpy="0 0 0" />
      <geometry>
        <mesh
          filename="package://vision1/meshes/left_front_wheel.STL" />
      </geometry>
      <material
        name="">
        <color
          rgba="1 0.698039215686274 0.309803921568627 1" />
      </material>
    </visual>
    <collision>
      <origin
        xyz="0 0 0"
        rpy="0 0 0" />
      <geometry>
        <mesh
          filename="package://vision1/meshes/left_front_wheel.STL" />
      </geometry>
    </collision>
  </link>
  <joint
    name="left_front_wheel_joint"
    type="continuous">
    <origin
      xyz="0 -0.41728 0"
      rpy="1.6033 0 0" />
    <parent
      link="left_front_whlconnect" />
    <child
      link="left_front_wheel" />
    <axis
      xyz="-1 0 0" />
  </joint>
  <link
    name="left_back_legs">
    <inertial>
      <origin
        xyz="-0.0281794914958189 -0.437137445244157 -0.127486719946212"
        rpy="0 0 0" />
      <mass
        value="32.7717928965034" />
      <inertia
        ixx="0.528659762782787"
        ixy="-0.00168610358511945"
        ixz="-2.39425252627351E-09"
        iyy="1.30533722923111"
        iyz="0.0435729279584516"
        izz="1.55489620389252" />
    </inertial>
    <visual>
      <origin
        xyz="0 0 0"
        rpy="0 0 0" />
      <geometry>
        <mesh
          filename="package://vision1/meshes/left_back_legs.STL" />
      </geometry>
      <material
        name="">
        <color
          rgba="0.792156862745098 0.819607843137255 0.933333333333333 1" />
      </material>
    </visual>
    <collision>
      <origin
        xyz="0 0 0"
        rpy="0 0 0" />
      <geometry>
        <mesh
          filename="package://vision1/meshes/left_back_legs.STL" />
      </geometry>
    </collision>
  </link>
  <joint
    name="left_back_legs_joint"
    type="fixed">
    <origin
      xyz="0.787846202409768 -0.138918542133536 0"
      rpy="3.14159265358979 0 -3.11008088957071" />
    <parent
      link="left_main" />
    <child
      link="left_back_legs" />
    <axis
      xyz="0 0 1" />
    
  </joint>
  <link
    name="left_back1">
    <inertial>
      <origin
        xyz="-0.169127296732301 1.11022302462516E-15 -4.9293902293357E-14"
        rpy="0 0 0" />
      <mass
        value="24.6135816790047" />
      <inertia
        ixx="1.49233859783079"
        ixy="5.42400245263348E-11"
        ixz="5.59704961659011E-11"
        iyy="0.941453197285768"
        iyz="5.79536418854332E-14"
        izz="0.941453197282358" />
    </inertial>
    <visual>
      <origin
        xyz="0 0 0"
        rpy="0 0 0" />
      <geometry>
        <mesh
          filename="package://vision1/meshes/left_back1.STL" />
      </geometry>
      <material
        name="">
        <color
          rgba="1 0.698039215686274 0.309803921568627 1" />
      </material>
    </visual>
    <collision>
      <origin
        xyz="0 0 0"
        rpy="0 0 0" />
      <geometry>
        <mesh
          filename="package://vision1/meshes/left_back1.STL" />
      </geometry>
    </collision>
  </link>
  <joint
    name="left_back1_joint"
    type="continuous">
    <origin
      xyz="0.489099860471848 -0.73355703444109 -0.0675004913212019"
      rpy="0.550131778527197 -1.5707963267949 0" />
    <parent
      link="left_back_legs" />
    <child
      link="left_back1" />
    <axis
      xyz="-1 0 0" />
  </joint>
  <link
    name="left_back2">
    <inertial>
      <origin
        xyz="-0.1691272967323 4.10782519111308E-15 -2.66453525910038E-14"
        rpy="0 0 0" />
      <mass
        value="24.6135816790048" />
      <inertia
        ixx="1.49233859783079"
        ixy="4.33631821911831E-11"
        ixz="6.47740021097192E-11"
        iyy="0.941453197285644"
        iyz="6.52568277192955E-13"
        izz="0.941453197282488" />
    </inertial>
    <visual>
      <origin
        xyz="0 0 0"
        rpy="0 0 0" />
      <geometry>
        <mesh
          filename="package://vision1/meshes/left_back2.STL" />
      </geometry>
      <material
        name="">
        <color
          rgba="1 0.698039215686274 0.309803921568627 1" />
      </material>
    </visual>
    <collision>
      <origin
        xyz="0 0 0"
        rpy="0 0 0" />
      <geometry>
        <mesh
          filename="package://vision1/meshes/left_back2.STL" />
      </geometry>
    </collision>
  </link>
  <joint
    name="left_back2_joint"
    type="continuous">
    <origin
      xyz="-0.5789 -0.73356 -0.0675"
      rpy="0.18028 -1.5708 0" />
    <parent
      link="left_back_legs" />
    <child
      link="left_back2" />
    <axis
      xyz="-1 0 0" />
  </joint>
  <link
    name="right_main">
    <inertial>
      <origin
        xyz="-0.187587214227297 -0.193829326981754 -0.0406494575529919"
        rpy="0 0 0" />
      <mass
        value="11.5796588524314" />
      <inertia
        ixx="0.104962702548715"
        ixy="-0.23703186835524"
        ixz="0.00841575862360529"
        iyy="2.53477008510846"
        iyz="-0.000365251532953653"
        izz="2.62636682146623" />
    </inertial>
    <visual>
      <origin
        xyz="0 0 0"
        rpy="0 0 0" />
      <geometry>
        <mesh
          filename="package://vision1/meshes/right_main.STL" />
      </geometry>
      <material
        name="">
        <color
          rgba="0.792156862745098 0.819607843137255 0.933333333333333 1" />
      </material>
    </visual>
    <collision>
      <origin
        xyz="0 0 0"
        rpy="0 0 0" />
      <geometry>
        <mesh
          filename="package://vision1/meshes/right_main.STL" />
      </geometry>
    </collision>
  </link>
  <joint
    name="right_main_joint"
    type="fixed">
    <origin
      xyz="0 -1.06 0.152698331709587"
      rpy="1.5707963267949 0.121907833439833 -3.14159265358979" />
    <parent
      link="chassis" />
    <child
      link="right_main" />
    <axis
      xyz="0 0 -1" />
    <limit
      lower="0"
      upper="0.5"
      effort="100"
      velocity="10" />
  </joint>
  <link
    name="right_front_whlconnect">
    <inertial>
      <origin
        xyz="0.0919368788373003 -0.303078537800282 2.97808799842869E-09"
        rpy="0 0 0" />
      <mass
        value="10.0922799476844" />
      <inertia
        ixx="0.180451958547417"
        ixy="0.0217867820511865"
        ixz="1.1112765430088E-09"
        iyy="0.0734598583330069"
        iyz="5.98564286026851E-09"
        izz="0.2398511507263" />
    </inertial>
    <visual>
      <origin
        xyz="0 0 0"
        rpy="0 0 0" />
      <geometry>
        <mesh
          filename="package://vision1/meshes/right_front_whlconnect.STL" />
      </geometry>
      <material
        name="">
        <color
          rgba="0.792156862745098 0.819607843137255 0.933333333333333 1" />
      </material>
    </visual>
    <collision>
      <origin
        xyz="0 0 0"
        rpy="0 0 0" />
      <geometry>
        <mesh
          filename="package://vision1/meshes/right_front_whlconnect.STL" />
      </geometry>
    </collision>
  </link>
  <joint
    name="right_front_whlconnect_joint"
    type="revolute">
    <origin
      xyz="-0.780900139528152 -0.460215775817232 -0.0400004913212026"
      rpy="0 -1.52350221998585 0" />
    <parent
      link="right_main" />
    <child
      link="right_front_whlconnect" />
    <axis
      xyz="0 1 0" />
    <limit
      lower="-1.0"
      upper="1.0"
      effort="100"
      velocity="10" />
  </joint>
  <link
    name="right_front_wheel">
    <inertial>
      <origin
        xyz="-0.072627296732299 1.11022302462516E-15 2.81025203108243E-14"
        rpy="0 0 0" />
      <mass
        value="24.6135816790047" />
      <inertia
        ixx="1.49233859783079"
        ixy="-5.42478666154533E-11"
        ixz="-5.59715190862065E-11"
        iyy="0.94145319728577"
        iyz="5.77471013715747E-14"
        izz="0.941453197282356" />
    </inertial>
    <visual>
      <origin
        xyz="0 0 0"
        rpy="0 0 0" />
      <geometry>
        <mesh
          filename="package://vision1/meshes/right_front_wheel.STL" />
      </geometry>
      <material
        name="">
        <color
          rgba="1 0.698039215686274 0.309803921568627 1" />
      </material>
    </visual>
    <collision>
      <origin
        xyz="0 0 0"
        rpy="0 0 0" />
      <geometry>
        <mesh
          filename="package://vision1/meshes/right_front_wheel.STL" />
      </geometry>
    </collision>
  </link>
  <joint
    name="right_front_wheel_joint"
    type="continuous">
    <origin
      xyz="0 -0.417276705070479 0"
      rpy="-0.91003225529218 0 0" />
    <parent
      link="right_front_whlconnect" />
    <child
      link="right_front_wheel" />
    <axis
      xyz="1 0 0" />
  </joint>
  <link
    name="right_back_legs">
    <inertial>
      <origin
        xyz="-0.0281794878273326 -0.437137445244157 0.0712631174309957"
        rpy="0 0 0" />
      <mass
        value="32.7717928965034" />
      <inertia
        ixx="0.528659762782786"
        ixy="-0.0016860796425448"
        ixz="-2.39425198417242E-09"
        iyy="1.3053372292311"
        iyz="-0.0435742002462945"
        izz="1.55489620389252" />
    </inertial>
    <visual>
      <origin
        xyz="0 0 0"
        rpy="0 0 0" />
      <geometry>
        <mesh
          filename="package://vision1/meshes/right_back_legs.STL" />
      </geometry>
      <material
        name="">
        <color
          rgba="0.792156862745098 0.819607843137255 0.933333333333333 1" />
      </material>
    </visual>
    <collision>
      <origin
        xyz="0 0 0"
        rpy="0 0 0" />
      <geometry>
        <mesh
          filename="package://vision1/meshes/right_back_legs.STL" />
      </geometry>
    </collision>
  </link>
  <joint
    name="right_back_legs_joint"
    type="fixed">
    <origin
      xyz="0.787846202409768 -0.138918542133536 0"
      rpy="3.14159265358979 0 -3.11008088957079" />
    <parent
      link="right_main" />
    <child
      link="right_back_legs" />
    <axis
      xyz="0 0 1" />
    
  </joint>
  <link
    name="right_back1">
    <inertial>
      <origin
        xyz="-0.169127296732299 -1.15463194561016E-14 3.37507799486048E-14"
        rpy="0 0 0" />
      <mass
        value="24.6135816790047" />
      <inertia
        ixx="1.49233859783079"
        ixy="-5.42406314479416E-11"
        ixz="-5.59701606763816E-11"
        iyy="0.941453197285769"
        iyz="5.6621374255883E-14"
        izz="0.941453197282355" />
    </inertial>
    <visual>
      <origin
        xyz="0 0 0"
        rpy="0 0 0" />
      <geometry>
        <mesh
          filename="package://vision1/meshes/right_back1.STL" />
      </geometry>
      <material
        name="">
        <color
          rgba="1 0.698039215686274 0.309803921568627 1" />
      </material>
    </visual>
    <collision>
      <origin
        xyz="0 0 0"
        rpy="0 0 0" />
      <geometry>
        <mesh
          filename="package://vision1/meshes/right_back1.STL" />
      </geometry>
    </collision>
  </link>
  <joint
    name="right_back1_joint"
    type="continuous">
    <origin
      xyz="0.489099860471849 -0.733557034441089 0.00149950867879678"
      rpy="1.16753517553023 1.5707963267949 0" />
    <parent
      link="right_back_legs" />
    <child
      link="right_back1" />
    <axis
      xyz="1 0 0" />
  </joint>
  <link
    name="right_back2">
    <inertial>
      <origin
        xyz="-0.1691272967323 1.85422410758918E-09 7.76871900143306E-11"
        rpy="0 0 0" />
      <mass
        value="24.6135816790047" />
      <inertia
        ixx="1.49233859783079"
        ixy="-6.09386535568011E-09"
        ixz="-3.08930789097044E-10"
        iyy="0.941453197285773"
        iyz="5.94533361530391E-14"
        izz="0.941453197282358" />
    </inertial>
    <visual>
      <origin
        xyz="0 0 0"
        rpy="0 0 0" />
      <geometry>
        <mesh
          filename="package://vision1/meshes/right_back2.STL" />
      </geometry>
      <material
        name="">
        <color
          rgba="1 0.698039215686274 0.309803921568627 1" />
      </material>
    </visual>
    <collision>
      <origin
        xyz="0 0 0"
        rpy="0 0 0" />
      <geometry>
        <mesh
          filename="package://vision1/meshes/right_back2.STL" />
      </geometry>
    </collision>
  </link>
  <joint
    name="right_back2_joint"
    type="continuous">
    <origin
      xyz="-0.578900139528151 -0.73355703444109 0.00149950867879678"
      rpy="0.0499724498475259 1.5707963267949 0" />
    <parent
      link="right_back_legs" />
    <child
      link="right_back2" />
    <axis
      xyz="1 0 0" />
  </joint>
  <link
    name="manipulator_base">
    <inertial>
      <origin
        xyz="6.99102964922223E-06 0.0184354408078916 0.000159353466286261"
        rpy="0 0 0" />
      <mass
        value="1.37953968759469" />
      <inertia
        ixx="0.0035265384613163"
        ixy="2.40342098945956E-07"
        ixz="-1.46510077494015E-07"
        iyy="0.00649710141935057"
        iyz="-6.08962678355607E-07"
        izz="0.00349684266480233" />
    </inertial>
    <visual>
      <origin
        xyz="0 0 0"
        rpy="0 0 0" />
      <geometry>
        <mesh
          filename="package://vision1/meshes/manipulator_base.STL" />
      </geometry>
      <material
        name="">
        <color
          rgba="0.792156862745098 0.819607843137255 0.933333333333333 1" />
      </material>
    </visual>
    <collision>
      <origin
        xyz="0 0 0"
        rpy="0 0 0" />
      <geometry>
        <mesh
          filename="package://vision1/meshes/manipulator_base.STL" />
      </geometry>
    </collision>
  </link>
  <joint
    name="manipulator_base_joint"
    type="fixed">
    <origin
      xyz="1.10476444145715 0 0.0173071919115596"
      rpy="1.5707963267949 0 1.5707963267949" />
    <parent
      link="chassis" />
    <child
      link="manipulator_base" />
    <axis
      xyz="0 0 0" />
  </joint>
  <link
    name="motor1">
    <inertial>
      <origin
        xyz="3.29536758787718E-06 0.130986521289339 -0.0144792084589447"
        rpy="0 0 0" />
      <mass
        value="6.00302462460103" />
      <inertia
        ixx="0.035025387809049"
        ixy="-3.04848720836574E-06"
        ixz="6.90689798253695E-07"
        iyy="0.0308829833133846"
        iyz="0.0026200542648932"
        izz="0.0327045356190031" />
    </inertial>
    <visual>
      <origin
        xyz="0 0 0"
        rpy="0 0 0" />
      <geometry>
        <mesh
          filename="package://vision1/meshes/motor1.STL" />
      </geometry>
      <material
        name="">
        <color
          rgba="0.792156862745098 0.819607843137255 0.933333333333333 1" />
      </material>
    </visual>
    <collision>
      <origin
        xyz="0 0 0"
        rpy="0 0 0" />
      <geometry>
        <mesh
          filename="package://vision1/meshes/motor1.STL" />
      </geometry>
    </collision>
  </link>
  <joint
    name="motor1_joint"
    type="revolute">
    <origin
      xyz="0 0.01 0"
      rpy="3.14159265358979 -0.107234786070816 3.14159265358979" />
    <parent
      link="manipulator_base" />
    <child
      link="motor1" />
    <axis
      xyz="0 1 0" />
    <limit
      lower="-3.14"
      upper="3.14"
      effort="100"
      velocity="10" />
  </joint>
  <link
    name="motor2">
    <inertial>
      <origin
        xyz="0.0993313193322516 0.301282797125642 -0.0888744458903575"
        rpy="0 0 0" />
      <mass
        value="17.0164903741412" />
      <inertia
        ixx="0.289942203754201"
        ixy="0.00274423220260284"
        ixz="-0.000215137998023459"
        iyy="0.0751805407800863"
        iyz="0.0566445339756234"
        izz="0.279895917847063" />
    </inertial>
    <visual>
      <origin
        xyz="0 0 0"
        rpy="0 0 0" />
      <geometry>
        <mesh
          filename="package://vision1/meshes/motor2.STL" />
      </geometry>
      <material
        name="">
        <color
          rgba="0.752941176470588 0.752941176470588 0.752941176470588 1" />
      </material>
    </visual>
    <collision>
      <origin
        xyz="0 0 0"
        rpy="0 0 0" />
      <geometry>
        <mesh
          filename="package://vision1/meshes/motor2.STL" />
      </geometry>
    </collision>
  </link>
  <joint
    name="motor2_joint"
    type="revolute">
    <origin
      xyz="0 0.14251 -0.10664"
      rpy="0 1.4636 -0.2937" />
    <parent
      link="motor1" />
    <child
      link="motor2" />
    <axis
      xyz="0.99426 0 -0.10703" />
    <limit
      lower="-3.14"
      upper="3.14"
      effort="100"
      velocity="10" />
  </joint>
  <link
    name="motor3">
    <inertial>
      <origin
        xyz="2.50985222405298E-06 0.14601062513625 0.162369115763925"
        rpy="0 0 0" />
      <mass
        value="9.59690667249651" />
      <inertia
        ixx="0.169816438571014"
        ixy="3.26085813121685E-06"
        ixz="1.00534544886233E-06"
        iyy="0.130137949611244"
        iyz="-0.0027332362396029"
        izz="0.169565077733242" />
    </inertial>
    <visual>
      <origin
        xyz="0 0 0"
        rpy="0 0 0" />
      <geometry>
        <mesh
          filename="package://vision1/meshes/motor3.STL" />
      </geometry>
      <material
        name="">
        <color
          rgba="0.792156862745098 0.819607843137255 0.933333333333333 1" />
      </material>
    </visual>
    <collision>
      <origin
        xyz="0 0 0"
        rpy="0 0 0" />
      <geometry>
        <mesh
          filename="package://vision1/meshes/motor3.STL" />
      </geometry>
    </collision>
  </link>
  <joint
    name="motor3_joint"
    type="revolute">
    <origin
      xyz="0.081311 0.74119 -0.20118"
      rpy="-1.8069 1.1343 -1.7834" />
    <parent
      link="motor2" />
    <child
      link="motor3" />
    <axis
      xyz="0 0 1" />
    <limit
      lower="-3.14"
      upper="3.14"
      effort="100"
      velocity="10" />
  </joint>
  <transmission name="simple_trans1">
    <type>transmission_interface/SimpleTransmission</type>
    <joint name="right_front_whlconnect_joint">
      <hardwareInterface>EffortJointInterface</hardwareInterface>
    </joint>
    <actuator name="right_front_whlconnect_act">
      <mechanicalReduction>50</mechanicalReduction>
      <hardwareInterface>EffortJointInterface</hardwareInterface>
    </actuator>
  </transmission>
  
  <transmission name="simple_trans2">
    <type>transmission_interface/SimpleTransmission</type>
    <joint name="right_back1_joint">
      <hardwareInterface>VelocityJointInterface</hardwareInterface>
    </joint>
    <actuator name="right_back1_act">
      <mechanicalReduction>50</mechanicalReduction>
      <hardwareInterface>VelocityJointInterface</hardwareInterface>
    </actuator>
  </transmission>
 
  
 
  
  <transmission name="simple_trans3">
    <type>transmission_interface/SimpleTransmission</type>
    <joint name="right_back2_joint">
      <hardwareInterface>VelocityJointInterface</hardwareInterface>
    </joint>
    <actuator name="right_back2_act">
      <mechanicalReduction>50</mechanicalReduction>
      <hardwareInterface>VelocityJointInterface</hardwareInterface>
    </actuator>
  </transmission>
  
  
  
  <transmission name="simple_trans4">
    <type>transmission_interface/SimpleTransmission</type>
    <joint name="left_front_whlconnect_joint">
      <hardwareInterface>EffortJointInterface</hardwareInterface>
    </joint>
    <actuator name="left_front_whlconnect_act">
      <mechanicalReduction>50</mechanicalReduction>
      <hardwareInterface>EffortJointInterface</hardwareInterface>
    </actuator>
  </transmission>
  
  <transmission name="simple_trans5">
    <type>transmission_interface/SimpleTransmission</type>
    <joint name="left_back1_joint">
      <hardwareInterface>VelocityJointInterface</hardwareInterface>
    </joint>
    <actuator name="left_back1_act">
      <mechanicalReduction>50</mechanicalReduction>
      <hardwareInterface>VelocityJointInterface</hardwareInterface>
    </actuator>
  </transmission>
 
  
  <transmission name="simple_trans6">
    <type>transmission_interface/SimpleTransmission</type>
    <joint name="left_back2_joint">
      <hardwareInterface>VelocityJointInterface</hardwareInterface>
    </joint>
    <actuator name="left_back2_act">
      <mechanicalReduction>50</mechanicalReduction>
      <hardwareInterface>VelocityJointInterface</hardwareInterface>
    </actuator>
  </transmission>
  
  <transmission name="simple_trans9">
    <type>transmission_interface/SimpleTransmission</type>
    <joint name="motor1_joint">
      <hardwareInterface>EffortJointInterface</hardwareInterface>
    </joint>
    <actuator name="motor1_act">
      <mechanicalReduction>50</mechanicalReduction>
      <hardwareInterface>EffortJointInterface</hardwareInterface>
    </actuator>
  </transmission>
  <transmission name="simple_trans10">
    <type>transmission_interface/SimpleTransmission</type>
    <joint name="motor2_joint">
      <hardwareInterface>EffortJointInterface</hardwareInterface>
    </joint>
    <actuator name="motor2_act">
      <mechanicalReduction>50</mechanicalReduction>
      <hardwareInterface>EffortJointInterface</hardwareInterface>
    </actuator>
  </transmission>
 
  
  <transmission name="simple_trans11">
    <type>transmission_interface/SimpleTransmission</type>
    <joint name="motor3_joint">
      <hardwareInterface>EffortJointInterface</hardwareInterface>
    </joint>
    <actuator name="motor3_act">
      <mechanicalReduction>50</mechanicalReduction>
      <hardwareInterface>EffortJointInterface</hardwareInterface>
    </actuator>
  </transmission>
  <gazebo>
    <plugin name="gazebo_ros_control" filename="libgazebo_ros_control.so">
      <robotNamespace>/vision1</robotNamespace>
      <robotSimType>gazebo_ros_control/DefaultRobotHWSim </robotSimType>
      <legacyModeNS>true</legacyModeNS>
    </plugin>
  </gazebo>
</robot>